Workbook

Sheet Kangatang

Sheet Ca nhan
O1: (Mẫu 01)
B2: BẢNG THỐNG KÊ GIỜ CHUẨN VƯỢT ĐỊNH MỨC CÁ NHÂN
B3: Đơn vị: | D3: Khoa Tăng thiết giáp | J3: Bộ môn: | L3: ….
B4: Họ tên nhà giáo: | D4: Đào Công T | J4: Chức vụ: | L4: Giảng viên
B5: Định mức giờ chuẩn giảng dạy: | E5: =IFERROR(VLOOKUP(L4, 'Quy doi'!$A$3:$B$25, 2, FALSE), "") -> 1 | J5: Số tháng không công tác tại khoa: | P5: 4
B6: 1. Quy đổi giờ chuẩn giảng dạy đã thực hiện
B8: Lớp | C8: Quân số | D8: Môn học, Nội dung | E8: Số tiết tham gia giảng dạy | J8: Kiểm tra định kỳ | M8: Thi kết thúc học phần | Q8: Tổng số tiết giảng dạy | R8: Số giờ chuẩn quy đổi | S8: Ghi chú (Ghi số tờ trong TKB, Số KH)
E9: Lý thuyết, thực hành, thí nghiệm, hướng dẫn tập bài | I9: Lái xe TTG, xe QS; TH chiến thuật, DT bắn đạn thật; tiếng nước ngoài* | J9: Hình thức kiểm tra | K9: Số lượng đề kiểm tra | L9: Số tiết kiểm tra | M9: Biên soạn, hiệu chỉnh | N9: Hình thức thi | O9: Số lượng đề thi | P9: Số tiết coi thi
E10: Giảng đường | G10: Xưởng TH, thao trường
E11: Ngày | F11: Đêm | G11: Ngày | H11: Đêm
B12: 26SQTL36151 | C12: 10 | D12: LTTG | Q12: =IF(COUNT(E12:I12,L12)=0,"",SUM(E12:I12,L12)) | R12: =IF(COUNTA(B12:P12)=0,"",ROUND(E12+F12*1.2+G12*1.2+H12*1.5+I12*2+K12*50%*IF(J12="TN",2,IF(J12="Viết",1.5,IF(J12="TH",1,IF(J12="VĐ",0.75,0))))+IF(J12="TN",L12*0.3*50%+C12*0.1*50%,IF(J12="Viết",L12*0.3*50%+C12*0.2*50%,IF(J12="VĐ",L12*0.5*50%,IF(J12="TH",L12*0.75*50%,0))))+O12*IF(M12="BS",1,IF(M12="HC",25%,0))*IF(N12="TN",2,IF(N12="Viết",1.5,IF(N12="TH",1,IF(N12="VĐ",0.75,0))))+IF(N12="TN",P12*0.3+C12*0.1,IF(N12="Viết",P12*0.3+C12*0.2,IF(N12="VĐ",P12*0.5,IF(N12="TH",P12*0.75,0)))),1)) -> 0 | S12: KH/QĐ số…
B13: 17DQS07111 | C13: 15 | D13: D06VKBB | Q13: =IF(COUNT(E13:I13,L13)=0,"",SUM(E13:I13,L13)) | R13: =IF(COUNTA(B13:P13)=0,"",ROUND(E13+F13*1.2+G13*1.2+H13*1.5+I13*2+K13*50%*IF(J13="TN",2,IF(J13="Viết",1.5,IF(J13="TH",1,IF(J13="VĐ",0.75,0))))+IF(J13="TN",L13*0.3*50%+C13*0.1*50%,IF(J13="Viết",L13*0.3*50%+C13*0.2*50%,IF(J13="VĐ",L13*0.5*50%,IF(J13="TH",L13*0.75*50%,0))))+O13*IF(M13="BS",1,IF(M13="HC",25%,0))*IF(N13="TN",2,IF(N13="Viết",1.5,IF(N13="TH",1,IF(N13="VĐ",0.75,0))))+IF(N13="TN",P13*0.3+C13*0.1,IF(N13="Viết",P13*0.3+C13*0.2,IF(N13="VĐ",P13*0.5,IF(N13="TH",P13*0.75,0)))),1)) -> 0 | S13: Tờ …/HK1
B14: 17DQS07111 | C14: 10 | D14: Diễn tập | Q14: =IF(COUNT(E14:I14,L14)=0,"",SUM(E14:I14,L14)) | R14: =IF(COUNTA(B14:P14)=0,"",ROUND(E14+F14*1.2+G14*1.2+H14*1.5+I14*2+K14*50%*IF(J14="TN",2,IF(J14="Viết",1.5,IF(J14="TH",1,IF(J14="VĐ",0.75,0))))+IF(J14="TN",L14*0.3*50%+C14*0.1*50%,IF(J14="Viết",L14*0.3*50%+C14*0.2*50%,IF(J14="VĐ",L14*0.5*50%,IF(J14="TH",L14*0.75*50%,0))))+O14*IF(M14="BS",1,IF(M14="HC",25%,0))*IF(N14="TN",2,IF(N14="Viết",1.5,IF(N14="TH",1,IF(N14="VĐ",0.75,0))))+IF(N14="TN",P14*0.3+C14*0.1,IF(N14="Viết",P14*0.3+C14*0.2,IF(N14="VĐ",P14*0.5,IF(N14="TH",P14*0.75,0)))),1)) -> 0 | S14: KH số…
Q15: =IF(COUNT(E15:I15,L15)=0,"",SUM(E15:I15,L15)) | R15: =IF(COUNTA(B15:P15)=0,"",ROUND(E15+F15*1.2+G15*1.2+H15*1.5+I15*2+K15*50%*IF(J15="TN",2,IF(J15="Viết",1.5,IF(J15="TH",1,IF(J15="VĐ",0.75,0))))+IF(J15="TN",L15*0.3*50%+C15*0.1*50%,IF(J15="Viết",L15*0.3*50%+C15*0.2*50%,IF(J15="VĐ",L15*0.5*50%,IF(J15="TH",L15*0.75*50%,0))))+O15*IF(M15="BS",1,IF(M15="HC",25%,0))*IF(N15="TN",2,IF(N15="Viết",1.5,IF(N15="TH",1,IF(N15="VĐ",0.75,0))))+IF(N15="TN",P15*0.3+C15*0.1,IF(N15="Viết",P15*0.3+C15*0.2,IF(N15="VĐ",P15*0.5,IF(N15="TH",P15*0.75,0)))),1))
Q16: =IF(COUNT(E16:I16,L16)=0,"",SUM(E16:I16,L16)) | R16: =IF(COUNTA(B16:P16)=0,"",ROUND(E16+F16*1.2+G16*1.2+H16*1.5+I16*2+K16*50%*IF(J16="TN",2,IF(J16="Viết",1.5,IF(J16="TH",1,IF(J16="VĐ",0.75,0))))+IF(J16="TN",L16*0.3*50%+C16*0.1*50%,IF(J16="Viết",L16*0.3*50%+C16*0.2*50%,IF(J16="VĐ",L16*0.5*50%,IF(J16="TH",L16*0.75*50%,0))))+O16*IF(M16="BS",1,IF(M16="HC",25%,0))*IF(N16="TN",2,IF(N16="Viết",1.5,IF(N16="TH",1,IF(N16="VĐ",0.75,0))))+IF(N16="TN",P16*0.3+C16*0.1,IF(N16="Viết",P16*0.3+C16*0.2,IF(N16="VĐ",P16*0.5,IF(N16="TH",P16*0.75,0)))),1))
Q17: =IF(COUNT(E17:I17,L17)=0,"",SUM(E17:I17,L17)) | R17: =IF(COUNTA(B17:P17)=0,"",ROUND(E17+F17*1.2+G17*1.2+H17*1.5+I17*2+K17*50%*IF(J17="TN",2,IF(J17="Viết",1.5,IF(J17="TH",1,IF(J17="VĐ",0.75,0))))+IF(J17="TN",L17*0.3*50%+C17*0.1*50%,IF(J17="Viết",L17*0.3*50%+C17*0.2*50%,IF(J17="VĐ",L17*0.5*50%,IF(J17="TH",L17*0.75*50%,0))))+O17*IF(M17="BS",1,IF(M17="HC",25%,0))*IF(N17="TN",2,IF(N17="Viết",1.5,IF(N17="TH",1,IF(N17="VĐ",0.75,0))))+IF(N17="TN",P17*0.3+C17*0.1,IF(N17="Viết",P17*0.3+C17*0.2,IF(N17="VĐ",P17*0.5,IF(N17="TH",P17*0.75,0)))),1))
Q18: =IF(COUNT(E18:I18,L18)=0,"",SUM(E18:I18,L18)) | R18: =IF(COUNTA(B18:P18)=0,"",ROUND(E18+F18*1.2+G18*1.2+H18*1.5+I18*2+K18*50%*IF(J18="TN",2,IF(J18="Viết",1.5,IF(J18="TH",1,IF(J18="VĐ",0.75,0))))+IF(J18="TN",L18*0.3*50%+C18*0.1*50%,IF(J18="Viết",L18*0.3*50%+C18*0.2*50%,IF(J18="VĐ",L18*0.5*50%,IF(J18="TH",L18*0.75*50%,0))))+O18*IF(M18="BS",1,IF(M18="HC",25%,0))*IF(N18="TN",2,IF(N18="Viết",1.5,IF(N18="TH",1,IF(N18="VĐ",0.75,0))))+IF(N18="TN",P18*0.3+C18*0.1,IF(N18="Viết",P18*0.3+C18*0.2,IF(N18="VĐ",P18*0.5,IF(N18="TH",P18*0.75,0)))),1))
Q19: =IF(COUNT(E19:I19,L19)=0,"",SUM(E19:I19,L19)) | R19: =IF(COUNTA(B19:P19)=0,"",ROUND(E19+F19*1.2+G19*1.2+H19*1.5+I19*2+K19*50%*IF(J19="TN",2,IF(J19="Viết",1.5,IF(J19="TH",1,IF(J19="VĐ",0.75,0))))+IF(J19="TN",L19*0.3*50%+C19*0.1*50%,IF(J19="Viết",L19*0.3*50%+C19*0.2*50%,IF(J19="VĐ",L19*0.5*50%,IF(J19="TH",L19*0.75*50%,0))))+O19*IF(M19="BS",1,IF(M19="HC",25%,0))*IF(N19="TN",2,IF(N19="Viết",1.5,IF(N19="TH",1,IF(N19="VĐ",0.75,0))))+IF(N19="TN",P19*0.3+C19*0.1,IF(N19="Viết",P19*0.3+C19*0.2,IF(N19="VĐ",P19*0.5,IF(N19="TH",P19*0.75,0)))),1))
Q20: =IF(COUNT(E20:I20,L20)=0,"",SUM(E20:I20,L20)) | R20: =IF(COUNTA(B20:P20)=0,"",ROUND(E20+F20*1.2+G20*1.2+H20*1.5+I20*2+K20*50%*IF(J20="TN",2,IF(J20="Viết",1.5,IF(J20="TH",1,IF(J20="VĐ",0.75,0))))+IF(J20="TN",L20*0.3*50%+C20*0.1*50%,IF(J20="Viết",L20*0.3*50%+C20*0.2*50%,IF(J20="VĐ",L20*0.5*50%,IF(J20="TH",L20*0.75*50%,0))))+O20*IF(M20="BS",1,IF(M20="HC",25%,0))*IF(N20="TN",2,IF(N20="Viết",1.5,IF(N20="TH",1,IF(N20="VĐ",0.75,0))))+IF(N20="TN",P20*0.3+C20*0.1,IF(N20="Viết",P20*0.3+C20*0.2,IF(N20="VĐ",P20*0.5,IF(N20="TH",P20*0.75,0)))),1))
Q21: =IF(COUNT(E21:I21,L21)=0,"",SUM(E21:I21,L21)) | R21: =IF(COUNTA(B21:P21)=0,"",ROUND(E21+F21*1.2+G21*1.2+H21*1.5+I21*2+K21*50%*IF(J21="TN",2,IF(J21="Viết",1.5,IF(J21="TH",1,IF(J21="VĐ",0.75,0))))+IF(J21="TN",L21*0.3*50%+C21*0.1*50%,IF(J21="Viết",L21*0.3*50%+C21*0.2*50%,IF(J21="VĐ",L21*0.5*50%,IF(J21="TH",L21*0.75*50%,0))))+O21*IF(M21="BS",1,IF(M21="HC",25%,0))*IF(N21="TN",2,IF(N21="Viết",1.5,IF(N21="TH",1,IF(N21="VĐ",0.75,0))))+IF(N21="TN",P21*0.3+C21*0.1,IF(N21="Viết",P21*0.3+C21*0.2,IF(N21="VĐ",P21*0.5,IF(N21="TH",P21*0.75,0)))),1))
Q22: =IF(COUNT(E22:I22,L22)=0,"",SUM(E22:I22,L22)) | R22: =IF(COUNTA(B22:P22)=0,"",ROUND(E22+F22*1.2+G22*1.2+H22*1.5+I22*2+K22*50%*IF(J22="TN",2,IF(J22="Viết",1.5,IF(J22="TH",1,IF(J22="VĐ",0.75,0))))+IF(J22="TN",L22*0.3*50%+C22*0.1*50%,IF(J22="Viết",L22*0.3*50%+C22*0.2*50%,IF(J22="VĐ",L22*0.5*50%,IF(J22="TH",L22*0.75*50%,0))))+O22*IF(M22="BS",1,IF(M22="HC",25%,0))*IF(N22="TN",2,IF(N22="Viết",1.5,IF(N22="TH",1,IF(N22="VĐ",0.75,0))))+IF(N22="TN",P22*0.3+C22*0.1,IF(N22="Viết",P22*0.3+C22*0.2,IF(N22="VĐ",P22*0.5,IF(N22="TH",P22*0.75,0)))),1))
Q23: =IF(COUNT(E23:I23,L23)=0,"",SUM(E23:I23,L23)) | R23: =IF(COUNTA(B23:P23)=0,"",ROUND(E23+F23*1.2+G23*1.2+H23*1.5+I23*2+K23*50%*IF(J23="TN",2,IF(J23="Viết",1.5,IF(J23="TH",1,IF(J23="VĐ",0.75,0))))+IF(J23="TN",L23*0.3*50%+C23*0.1*50%,IF(J23="Viết",L23*0.3*50%+C23*0.2*50%,IF(J23="VĐ",L23*0.5*50%,IF(J23="TH",L23*0.75*50%,0))))+O23*IF(M23="BS",1,IF(M23="HC",25%,0))*IF(N23="TN",2,IF(N23="Viết",1.5,IF(N23="TH",1,IF(N23="VĐ",0.75,0))))+IF(N23="TN",P23*0.3+C23*0.1,IF(N23="Viết",P23*0.3+C23*0.2,IF(N23="VĐ",P23*0.5,IF(N23="TH",P23*0.75,0)))),1))
Q24: =IF(COUNT(E24:I24,L24)=0,"",SUM(E24:I24,L24)) | R24: =IF(COUNTA(B24:P24)=0,"",ROUND(E24+F24*1.2+G24*1.2+H24*1.5+I24*2+K24*50%*IF(J24="TN",2,IF(J24="Viết",1.5,IF(J24="TH",1,IF(J24="VĐ",0.75,0))))+IF(J24="TN",L24*0.3*50%+C24*0.1*50%,IF(J24="Viết",L24*0.3*50%+C24*0.2*50%,IF(J24="VĐ",L24*0.5*50%,IF(J24="TH",L24*0.75*50%,0))))+O24*IF(M24="BS",1,IF(M24="HC",25%,0))*IF(N24="TN",2,IF(N24="Viết",1.5,IF(N24="TH",1,IF(N24="VĐ",0.75,0))))+IF(N24="TN",P24*0.3+C24*0.1,IF(N24="Viết",P24*0.3+C24*0.2,IF(N24="VĐ",P24*0.5,IF(N24="TH",P24*0.75,0)))),1))
Q25: =IF(COUNT(E25:I25,L25)=0,"",SUM(E25:I25,L25)) | R25: =IF(COUNTA(B25:P25)=0,"",ROUND(E25+F25*1.2+G25*1.2+H25*1.5+I25*2+K25*50%*IF(J25="TN",2,IF(J25="Viết",1.5,IF(J25="TH",1,IF(J25="VĐ",0.75,0))))+IF(J25="TN",L25*0.3*50%+C25*0.1*50%,IF(J25="Viết",L25*0.3*50%+C25*0.2*50%,IF(J25="VĐ",L25*0.5*50%,IF(J25="TH",L25*0.75*50%,0))))+O25*IF(M25="BS",1,IF(M25="HC",25%,0))*IF(N25="TN",2,IF(N25="Viết",1.5,IF(N25="TH",1,IF(N25="VĐ",0.75,0))))+IF(N25="TN",P25*0.3+C25*0.1,IF(N25="Viết",P25*0.3+C25*0.2,IF(N25="VĐ",P25*0.5,IF(N25="TH",P25*0.75,0)))),1))
Q26: =IF(COUNT(E26:I26,L26)=0,"",SUM(E26:I26,L26)) | R26: =IF(COUNTA(B26:P26)=0,"",ROUND(E26+F26*1.2+G26*1.2+H26*1.5+I26*2+K26*50%*IF(J26="TN",2,IF(J26="Viết",1.5,IF(J26="TH",1,IF(J26="VĐ",0.75,0))))+IF(J26="TN",L26*0.3*50%+C26*0.1*50%,IF(J26="Viết",L26*0.3*50%+C26*0.2*50%,IF(J26="VĐ",L26*0.5*50%,IF(J26="TH",L26*0.75*50%,0))))+O26*IF(M26="BS",1,IF(M26="HC",25%,0))*IF(N26="TN",2,IF(N26="Viết",1.5,IF(N26="TH",1,IF(N26="VĐ",0.75,0))))+IF(N26="TN",P26*0.3+C26*0.1,IF(N26="Viết",P26*0.3+C26*0.2,IF(N26="VĐ",P26*0.5,IF(N26="TH",P26*0.75,0)))),1))
B27: TỔNG | E27: =SUM(E12:E26) -> 0 | F27: =SUM(F12:F26) -> 0 | G27: =SUM(G12:G26) -> 0 | H27: =SUM(H12:H26) -> 0 | I27: =SUM(I12:I26) -> 0 | K27: =SUM(K12:K26) -> 0 | L27: =SUM(L12:L26) -> 0 | O27: =SUM(O12:O26) -> 0 | P27: =SUM(P12:P26) -> 0 | Q27: =SUM(Q12:Q26) -> 0 | R27: =SUM(R12:R26) -> 0
B28: * Giảng dạy bằng tiếng nước ngoài cho môn học không phải môn ngoại ngữ.
B29: 2. Quy đổi giờ chuẩn NCKH đã thực hiện
B30: Sản phẩm khoa học | C30: Tên sản phẩm khoa học | I30: Cấp | J30: Số giờ hành chính thực hiện sản phẩm | L30: Số năm thực hiện | M30: Mức đánh giá | N30: Chức vụ | P30: Số lượng thành viên | Q30: Tỷ lệ đóng góp (%) | R30: Số giờ chuẩn quy đổi | S30: Ghi chú
B31: Đề tài | C31: Nghiên cứu đề xuất… | I31: Nhà trường | J31: =IFERROR(CHOOSE(MATCH(B31,'Quy doi'!$E$3:$E$8,0),CHOOSE(MATCH(I31,'Quy doi'!$F$4:$F$7,0),1200,1800,2400,3600),CHOOSE(MATCH(I31,'Quy doi'!$F$4:$F$7,0),300,450,600,900),IF(I31='Quy doi'!$F$4,CHOOSE(MATCH(M31,'Quy doi'!$G$3:$G$5,0),300,250,200),NA()),1200,IF(I31='Quy doi'!$F$11,CHOOSE(MATCH(M31,'Quy doi'!$G$6:$G$8,0),1200,1000,800),CHOOSE(MATCH(I31,'Quy doi'!$F$9:$F$10,0),300,600)),CHOOSE(MATCH(I31,'Quy doi'!$F$3:$F$8,0),100,200,300,450,600,600)),"") -> 1200 | L31: 1 | M31: Xuất sắc | N31: Tham gia | P31: 5 | Q31: 30 | R31: =IF(B31="","",IFERROR(IF(OR(NOT(ISNUMBER(J31)),J31<0),"Kiểm tra giờ hành chính",IF(OR(NOT(ISNUMBER(L31)),L31<=0),"Nhập số năm",IF(OR(NOT(ISNUMBER(P31)),P31<1,P31<>INT(P31)),"Số thành viên phải là số nguyên từ 1",IF(NOT(OR(TRIM(N31)="Chủ nhiệm",TRIM(N31)="Chủ biên",TRIM(N31)="Tác giả chính",TRIM(N31)="Tham gia")),"Chọn chức năng",IF(AND(Q31<>"",OR(NOT(ISNUMBER(Q31)),Q31<0,Q31>100)),"Tỷ lệ đóng góp phải từ 0 đến 100",IF(OR(NOT(ISNUMBER('Quy doi'!$J$5)),'Quy doi'!$J$5<>3),"Quy doi!J5 phải là số 3",ROUND(J31/L31/'Quy doi'!$J$5*IF(P31=1,1,IF(TRIM(N31)="Tham gia",0,IF(P31=2,2/3,IF(P31=3,1/2,1/3)))+(1-IF(P31=2,2/3,IF(P31=3,1/2,1/3)))*IF(ISNUMBER(Q31),Q31/100,1/P31)),1))))))),"Lỗi ở ô nguồn")) -> 80
B32: Sáng kiến tự bảo đảm | C32: Chế tạo thiết bị… | I32: Nhà trường | J32: =IFERROR(CHOOSE(MATCH(B32,'Quy doi'!$E$3:$E$8,0),CHOOSE(MATCH(I32,'Quy doi'!$F$4:$F$7,0),1200,1800,2400,3600),CHOOSE(MATCH(I32,'Quy doi'!$F$4:$F$7,0),300,450,600,900),IF(I32='Quy doi'!$F$4,CHOOSE(MATCH(M32,'Quy doi'!$G$3:$G$5,0),300,250,200),NA()),1200,IF(I32='Quy doi'!$F$11,CHOOSE(MATCH(M32,'Quy doi'!$G$6:$G$8,0),1200,1000,800),CHOOSE(MATCH(I32,'Quy doi'!$F$9:$F$10,0),300,600)),CHOOSE(MATCH(I32,'Quy doi'!$F$3:$F$8,0),100,200,300,450,600,600)),"") -> 300 | L32: 1 | M32: Xuất sắc | N32: Tham gia | P32: 2 | Q32: 60 | R32: =IF(B32="","",IFERROR(IF(OR(NOT(ISNUMBER(J32)),J32<0),"Kiểm tra giờ hành chính",IF(OR(NOT(ISNUMBER(L32)),L32<=0),"Nhập số năm",IF(OR(NOT(ISNUMBER(P32)),P32<1,P32<>INT(P32)),"Số thành viên phải là số nguyên từ 1",IF(NOT(OR(TRIM(N32)="Chủ nhiệm",TRIM(N32)="Chủ biên",TRIM(N32)="Tác giả chính",TRIM(N32)="Tham gia")),"Chọn chức năng",IF(AND(Q32<>"",OR(NOT(ISNUMBER(Q32)),Q32<0,Q32>100)),"Tỷ lệ đóng góp phải từ 0 đến 100",IF(OR(NOT(ISNUMBER('Quy doi'!$J$5)),'Quy doi'!$J$5<>3),"Quy doi!J5 phải là số 3",ROUND(J32/L32/'Quy doi'!$J$5*IF(P32=1,1,IF(TRIM(N32)="Tham gia",0,IF(P32=2,2/3,IF(P32=3,1/2,1/3)))+(1-IF(P32=2,2/3,IF(P32=3,1/2,1/3)))*IF(ISNUMBER(Q32),Q32/100,1/P32)),1))))))),"Lỗi ở ô nguồn")) -> 20
J33: =IFERROR(CHOOSE(MATCH(B33,'Quy doi'!$E$3:$E$8,0),CHOOSE(MATCH(I33,'Quy doi'!$F$4:$F$7,0),1200,1800,2400,3600),CHOOSE(MATCH(I33,'Quy doi'!$F$4:$F$7,0),300,450,600,900),IF(I33='Quy doi'!$F$4,CHOOSE(MATCH(M33,'Quy doi'!$G$3:$G$5,0),300,250,200),NA()),1200,IF(I33='Quy doi'!$F$11,CHOOSE(MATCH(M33,'Quy doi'!$G$6:$G$8,0),1200,1000,800),CHOOSE(MATCH(I33,'Quy doi'!$F$9:$F$10,0),300,600)),CHOOSE(MATCH(I33,'Quy doi'!$F$3:$F$8,0),100,200,300,450,600,600)),"") | R33: =IF(B33="","",IFERROR(IF(OR(NOT(ISNUMBER(J33)),J33<0),"Kiểm tra giờ hành chính",IF(OR(NOT(ISNUMBER(L33)),L33<=0),"Nhập số năm",IF(OR(NOT(ISNUMBER(P33)),P33<1,P33<>INT(P33)),"Số thành viên phải là số nguyên từ 1",IF(NOT(OR(TRIM(N33)="Chủ nhiệm",TRIM(N33)="Chủ biên",TRIM(N33)="Tác giả chính",TRIM(N33)="Tham gia")),"Chọn chức năng",IF(AND(Q33<>"",OR(NOT(ISNUMBER(Q33)),Q33<0,Q33>100)),"Tỷ lệ đóng góp phải từ 0 đến 100",IF(OR(NOT(ISNUMBER('Quy doi'!$J$5)),'Quy doi'!$J$5<>3),"Quy doi!J5 phải là số 3",ROUND(J33/L33/'Quy doi'!$J$5*IF(P33=1,1,IF(TRIM(N33)="Tham gia",0,IF(P33=2,2/3,IF(P33=3,1/2,1/3)))+(1-IF(P33=2,2/3,IF(P33=3,1/2,1/3)))*IF(ISNUMBER(Q33),Q33/100,1/P33)),1))))))),"Lỗi ở ô nguồn"))
J34: =IFERROR(CHOOSE(MATCH(B34,'Quy doi'!$E$3:$E$8,0),CHOOSE(MATCH(I34,'Quy doi'!$F$4:$F$7,0),1200,1800,2400,3600),CHOOSE(MATCH(I34,'Quy doi'!$F$4:$F$7,0),300,450,600,900),IF(I34='Quy doi'!$F$4,CHOOSE(MATCH(M34,'Quy doi'!$G$3:$G$5,0),300,250,200),NA()),1200,IF(I34='Quy doi'!$F$11,CHOOSE(MATCH(M34,'Quy doi'!$G$6:$G$8,0),1200,1000,800),CHOOSE(MATCH(I34,'Quy doi'!$F$9:$F$10,0),300,600)),CHOOSE(MATCH(I34,'Quy doi'!$F$3:$F$8,0),100,200,300,450,600,600)),"") | R34: =IF(B34="","",IFERROR(IF(OR(NOT(ISNUMBER(J34)),J34<0),"Kiểm tra giờ hành chính",IF(OR(NOT(ISNUMBER(L34)),L34<=0),"Nhập số năm",IF(OR(NOT(ISNUMBER(P34)),P34<1,P34<>INT(P34)),"Số thành viên phải là số nguyên từ 1",IF(NOT(OR(TRIM(N34)="Chủ nhiệm",TRIM(N34)="Chủ biên",TRIM(N34)="Tác giả chính",TRIM(N34)="Tham gia")),"Chọn chức năng",IF(AND(Q34<>"",OR(NOT(ISNUMBER(Q34)),Q34<0,Q34>100)),"Tỷ lệ đóng góp phải từ 0 đến 100",IF(OR(NOT(ISNUMBER('Quy doi'!$J$5)),'Quy doi'!$J$5<>3),"Quy doi!J5 phải là số 3",ROUND(J34/L34/'Quy doi'!$J$5*IF(P34=1,1,IF(TRIM(N34)="Tham gia",0,IF(P34=2,2/3,IF(P34=3,1/2,1/3)))+(1-IF(P34=2,2/3,IF(P34=3,1/2,1/3)))*IF(ISNUMBER(Q34),Q34/100,1/P34)),1))))))),"Lỗi ở ô nguồn"))
J35: =IFERROR(CHOOSE(MATCH(B35,'Quy doi'!$E$3:$E$8,0),CHOOSE(MATCH(I35,'Quy doi'!$F$4:$F$7,0),1200,1800,2400,3600),CHOOSE(MATCH(I35,'Quy doi'!$F$4:$F$7,0),300,450,600,900),IF(I35='Quy doi'!$F$4,CHOOSE(MATCH(M35,'Quy doi'!$G$3:$G$5,0),300,250,200),NA()),1200,IF(I35='Quy doi'!$F$11,CHOOSE(MATCH(M35,'Quy doi'!$G$6:$G$8,0),1200,1000,800),CHOOSE(MATCH(I35,'Quy doi'!$F$9:$F$10,0),300,600)),CHOOSE(MATCH(I35,'Quy doi'!$F$3:$F$8,0),100,200,300,450,600,600)),"") | R35: =IF(B35="","",IFERROR(IF(OR(NOT(ISNUMBER(J35)),J35<0),"Kiểm tra giờ hành chính",IF(OR(NOT(ISNUMBER(L35)),L35<=0),"Nhập số năm",IF(OR(NOT(ISNUMBER(P35)),P35<1,P35<>INT(P35)),"Số thành viên phải là số nguyên từ 1",IF(NOT(OR(TRIM(N35)="Chủ nhiệm",TRIM(N35)="Chủ biên",TRIM(N35)="Tác giả chính",TRIM(N35)="Tham gia")),"Chọn chức năng",IF(AND(Q35<>"",OR(NOT(ISNUMBER(Q35)),Q35<0,Q35>100)),"Tỷ lệ đóng góp phải từ 0 đến 100",IF(OR(NOT(ISNUMBER('Quy doi'!$J$5)),'Quy doi'!$J$5<>3),"Quy doi!J5 phải là số 3",ROUND(J35/L35/'Quy doi'!$J$5*IF(P35=1,1,IF(TRIM(N35)="Tham gia",0,IF(P35=2,2/3,IF(P35=3,1/2,1/3)))+(1-IF(P35=2,2/3,IF(P35=3,1/2,1/3)))*IF(ISNUMBER(Q35),Q35/100,1/P35)),1))))))),"Lỗi ở ô nguồn"))
J36: =IFERROR(CHOOSE(MATCH(B36,'Quy doi'!$E$3:$E$8,0),CHOOSE(MATCH(I36,'Quy doi'!$F$4:$F$7,0),1200,1800,2400,3600),CHOOSE(MATCH(I36,'Quy doi'!$F$4:$F$7,0),300,450,600,900),IF(I36='Quy doi'!$F$4,CHOOSE(MATCH(M36,'Quy doi'!$G$3:$G$5,0),300,250,200),NA()),1200,IF(I36='Quy doi'!$F$11,CHOOSE(MATCH(M36,'Quy doi'!$G$6:$G$8,0),1200,1000,800),CHOOSE(MATCH(I36,'Quy doi'!$F$9:$F$10,0),300,600)),CHOOSE(MATCH(I36,'Quy doi'!$F$3:$F$8,0),100,200,300,450,600,600)),"") | R36: =IF(B36="","",IFERROR(IF(OR(NOT(ISNUMBER(J36)),J36<0),"Kiểm tra giờ hành chính",IF(OR(NOT(ISNUMBER(L36)),L36<=0),"Nhập số năm",IF(OR(NOT(ISNUMBER(P36)),P36<1,P36<>INT(P36)),"Số thành viên phải là số nguyên từ 1",IF(NOT(OR(TRIM(N36)="Chủ nhiệm",TRIM(N36)="Chủ biên",TRIM(N36)="Tác giả chính",TRIM(N36)="Tham gia")),"Chọn chức năng",IF(AND(Q36<>"",OR(NOT(ISNUMBER(Q36)),Q36<0,Q36>100)),"Tỷ lệ đóng góp phải từ 0 đến 100",IF(OR(NOT(ISNUMBER('Quy doi'!$J$5)),'Quy doi'!$J$5<>3),"Quy doi!J5 phải là số 3",ROUND(J36/L36/'Quy doi'!$J$5*IF(P36=1,1,IF(TRIM(N36)="Tham gia",0,IF(P36=2,2/3,IF(P36=3,1/2,1/3)))+(1-IF(P36=2,2/3,IF(P36=3,1/2,1/3)))*IF(ISNUMBER(Q36),Q36/100,1/P36)),1))))))),"Lỗi ở ô nguồn"))
J37: =IFERROR(CHOOSE(MATCH(B37,'Quy doi'!$E$3:$E$8,0),CHOOSE(MATCH(I37,'Quy doi'!$F$4:$F$7,0),1200,1800,2400,3600),CHOOSE(MATCH(I37,'Quy doi'!$F$4:$F$7,0),300,450,600,900),IF(I37='Quy doi'!$F$4,CHOOSE(MATCH(M37,'Quy doi'!$G$3:$G$5,0),300,250,200),NA()),1200,IF(I37='Quy doi'!$F$11,CHOOSE(MATCH(M37,'Quy doi'!$G$6:$G$8,0),1200,1000,800),CHOOSE(MATCH(I37,'Quy doi'!$F$9:$F$10,0),300,600)),CHOOSE(MATCH(I37,'Quy doi'!$F$3:$F$8,0),100,200,300,450,600,600)),"") | R37: =IF(B37="","",IFERROR(IF(OR(NOT(ISNUMBER(J37)),J37<0),"Kiểm tra giờ hành chính",IF(OR(NOT(ISNUMBER(L37)),L37<=0),"Nhập số năm",IF(OR(NOT(ISNUMBER(P37)),P37<1,P37<>INT(P37)),"Số thành viên phải là số nguyên từ 1",IF(NOT(OR(TRIM(N37)="Chủ nhiệm",TRIM(N37)="Chủ biên",TRIM(N37)="Tác giả chính",TRIM(N37)="Tham gia")),"Chọn chức năng",IF(AND(Q37<>"",OR(NOT(ISNUMBER(Q37)),Q37<0,Q37>100)),"Tỷ lệ đóng góp phải từ 0 đến 100",IF(OR(NOT(ISNUMBER('Quy doi'!$J$5)),'Quy doi'!$J$5<>3),"Quy doi!J5 phải là số 3",ROUND(J37/L37/'Quy doi'!$J$5*IF(P37=1,1,IF(TRIM(N37)="Tham gia",0,IF(P37=2,2/3,IF(P37=3,1/2,1/3)))+(1-IF(P37=2,2/3,IF(P37=3,1/2,1/3)))*IF(ISNUMBER(Q37),Q37/100,1/P37)),1))))))),"Lỗi ở ô nguồn"))
J38: =IFERROR(CHOOSE(MATCH(B38,'Quy doi'!$E$3:$E$8,0),CHOOSE(MATCH(I38,'Quy doi'!$F$4:$F$7,0),1200,1800,2400,3600),CHOOSE(MATCH(I38,'Quy doi'!$F$4:$F$7,0),300,450,600,900),IF(I38='Quy doi'!$F$4,CHOOSE(MATCH(M38,'Quy doi'!$G$3:$G$5,0),300,250,200),NA()),1200,IF(I38='Quy doi'!$F$11,CHOOSE(MATCH(M38,'Quy doi'!$G$6:$G$8,0),1200,1000,800),CHOOSE(MATCH(I38,'Quy doi'!$F$9:$F$10,0),300,600)),CHOOSE(MATCH(I38,'Quy doi'!$F$3:$F$8,0),100,200,300,450,600,600)),"") | R38: =IF(B38="","",IFERROR(IF(OR(NOT(ISNUMBER(J38)),J38<0),"Kiểm tra giờ hành chính",IF(OR(NOT(ISNUMBER(L38)),L38<=0),"Nhập số năm",IF(OR(NOT(ISNUMBER(P38)),P38<1,P38<>INT(P38)),"Số thành viên phải là số nguyên từ 1",IF(NOT(OR(TRIM(N38)="Chủ nhiệm",TRIM(N38)="Chủ biên",TRIM(N38)="Tác giả chính",TRIM(N38)="Tham gia")),"Chọn chức năng",IF(AND(Q38<>"",OR(NOT(ISNUMBER(Q38)),Q38<0,Q38>100)),"Tỷ lệ đóng góp phải từ 0 đến 100",IF(OR(NOT(ISNUMBER('Quy doi'!$J$5)),'Quy doi'!$J$5<>3),"Quy doi!J5 phải là số 3",ROUND(J38/L38/'Quy doi'!$J$5*IF(P38=1,1,IF(TRIM(N38)="Tham gia",0,IF(P38=2,2/3,IF(P38=3,1/2,1/3)))+(1-IF(P38=2,2/3,IF(P38=3,1/2,1/3)))*IF(ISNUMBER(Q38),Q38/100,1/P38)),1))))))),"Lỗi ở ô nguồn"))
J39: =IFERROR(CHOOSE(MATCH(B39,'Quy doi'!$E$3:$E$8,0),CHOOSE(MATCH(I39,'Quy doi'!$F$4:$F$7,0),1200,1800,2400,3600),CHOOSE(MATCH(I39,'Quy doi'!$F$4:$F$7,0),300,450,600,900),IF(I39='Quy doi'!$F$4,CHOOSE(MATCH(M39,'Quy doi'!$G$3:$G$5,0),300,250,200),NA()),1200,IF(I39='Quy doi'!$F$11,CHOOSE(MATCH(M39,'Quy doi'!$G$6:$G$8,0),1200,1000,800),CHOOSE(MATCH(I39,'Quy doi'!$F$9:$F$10,0),300,600)),CHOOSE(MATCH(I39,'Quy doi'!$F$3:$F$8,0),100,200,300,450,600,600)),"") | R39: =IF(B39="","",IFERROR(IF(OR(NOT(ISNUMBER(J39)),J39<0),"Kiểm tra giờ hành chính",IF(OR(NOT(ISNUMBER(L39)),L39<=0),"Nhập số năm",IF(OR(NOT(ISNUMBER(P39)),P39<1,P39<>INT(P39)),"Số thành viên phải là số nguyên từ 1",IF(NOT(OR(TRIM(N39)="Chủ nhiệm",TRIM(N39)="Chủ biên",TRIM(N39)="Tác giả chính",TRIM(N39)="Tham gia")),"Chọn chức năng",IF(AND(Q39<>"",OR(NOT(ISNUMBER(Q39)),Q39<0,Q39>100)),"Tỷ lệ đóng góp phải từ 0 đến 100",IF(OR(NOT(ISNUMBER('Quy doi'!$J$5)),'Quy doi'!$J$5<>3),"Quy doi!J5 phải là số 3",ROUND(J39/L39/'Quy doi'!$J$5*IF(P39=1,1,IF(TRIM(N39)="Tham gia",0,IF(P39=2,2/3,IF(P39=3,1/2,1/3)))+(1-IF(P39=2,2/3,IF(P39=3,1/2,1/3)))*IF(ISNUMBER(Q39),Q39/100,1/P39)),1))))))),"Lỗi ở ô nguồn"))
J40: =IFERROR(CHOOSE(MATCH(B40,'Quy doi'!$E$3:$E$8,0),CHOOSE(MATCH(I40,'Quy doi'!$F$4:$F$7,0),1200,1800,2400,3600),CHOOSE(MATCH(I40,'Quy doi'!$F$4:$F$7,0),300,450,600,900),IF(I40='Quy doi'!$F$4,CHOOSE(MATCH(M40,'Quy doi'!$G$3:$G$5,0),300,250,200),NA()),1200,IF(I40='Quy doi'!$F$11,CHOOSE(MATCH(M40,'Quy doi'!$G$6:$G$8,0),1200,1000,800),CHOOSE(MATCH(I40,'Quy doi'!$F$9:$F$10,0),300,600)),CHOOSE(MATCH(I40,'Quy doi'!$F$3:$F$8,0),100,200,300,450,600,600)),"") | R40: =IF(B40="","",IFERROR(IF(OR(NOT(ISNUMBER(J40)),J40<0),"Kiểm tra giờ hành chính",IF(OR(NOT(ISNUMBER(L40)),L40<=0),"Nhập số năm",IF(OR(NOT(ISNUMBER(P40)),P40<1,P40<>INT(P40)),"Số thành viên phải là số nguyên từ 1",IF(NOT(OR(TRIM(N40)="Chủ nhiệm",TRIM(N40)="Chủ biên",TRIM(N40)="Tác giả chính",TRIM(N40)="Tham gia")),"Chọn chức năng",IF(AND(Q40<>"",OR(NOT(ISNUMBER(Q40)),Q40<0,Q40>100)),"Tỷ lệ đóng góp phải từ 0 đến 100",IF(OR(NOT(ISNUMBER('Quy doi'!$J$5)),'Quy doi'!$J$5<>3),"Quy doi!J5 phải là số 3",ROUND(J40/L40/'Quy doi'!$J$5*IF(P40=1,1,IF(TRIM(N40)="Tham gia",0,IF(P40=2,2/3,IF(P40=3,1/2,1/3)))+(1-IF(P40=2,2/3,IF(P40=3,1/2,1/3)))*IF(ISNUMBER(Q40),Q40/100,1/P40)),1))))))),"Lỗi ở ô nguồn"))
J41: =IFERROR(CHOOSE(MATCH(B41,'Quy doi'!$E$3:$E$8,0),CHOOSE(MATCH(I41,'Quy doi'!$F$4:$F$7,0),1200,1800,2400,3600),CHOOSE(MATCH(I41,'Quy doi'!$F$4:$F$7,0),300,450,600,900),IF(I41='Quy doi'!$F$4,CHOOSE(MATCH(M41,'Quy doi'!$G$3:$G$5,0),300,250,200),NA()),1200,IF(I41='Quy doi'!$F$11,CHOOSE(MATCH(M41,'Quy doi'!$G$6:$G$8,0),1200,1000,800),CHOOSE(MATCH(I41,'Quy doi'!$F$9:$F$10,0),300,600)),CHOOSE(MATCH(I41,'Quy doi'!$F$3:$F$8,0),100,200,300,450,600,600)),"") | R41: =IF(B41="","",IFERROR(IF(OR(NOT(ISNUMBER(J41)),J41<0),"Kiểm tra giờ hành chính",IF(OR(NOT(ISNUMBER(L41)),L41<=0),"Nhập số năm",IF(OR(NOT(ISNUMBER(P41)),P41<1,P41<>INT(P41)),"Số thành viên phải là số nguyên từ 1",IF(NOT(OR(TRIM(N41)="Chủ nhiệm",TRIM(N41)="Chủ biên",TRIM(N41)="Tác giả chính",TRIM(N41)="Tham gia")),"Chọn chức năng",IF(AND(Q41<>"",OR(NOT(ISNUMBER(Q41)),Q41<0,Q41>100)),"Tỷ lệ đóng góp phải từ 0 đến 100",IF(OR(NOT(ISNUMBER('Quy doi'!$J$5)),'Quy doi'!$J$5<>3),"Quy doi!J5 phải là số 3",ROUND(J41/L41/'Quy doi'!$J$5*IF(P41=1,1,IF(TRIM(N41)="Tham gia",0,IF(P41=2,2/3,IF(P41=3,1/2,1/3)))+(1-IF(P41=2,2/3,IF(P41=3,1/2,1/3)))*IF(ISNUMBER(Q41),Q41/100,1/P41)),1))))))),"Lỗi ở ô nguồn"))
...

Sheet Quy doi
A1: QUY ĐỔI TỶ LỆ GIẢNG DẠY - NGHIÊN CỨU KHOA HỌC
A2: Chức vụ | B2: Tỷ lệ GD | C2: Định mức GD | E2: Loại sản phẩm | F2: Cấp/danh mục | G2: Mức đánh giá | I2: Thông số | J2: Giá trị
A3: Hiệu trưởng | B3: 0.1 | C3: 28 | E3: Đề tài | F3: Khoa | G3: Xuất sắc | I3: Định mức GD gốc | J3: 280
A4: Chính ủy | B4: 0.1 | C4: 28 | E4: Sáng kiến | F4: Nhà trường | G4: Khá | I4: Định mức NCKH (giờ HC) | J4: 600
A5: Phó Hiệu trưởng | B5: 0.15 | C5: 42 | E5: Sáng kiến tự bảo đảm | F5: BTTM/TCCT/Tổng cục | G5: Đạt | I5: Giờ HC/giờ chuẩn | J5: 3
A6: Phó Chính ủy | B6: 0.15 | C6: 42 | E6: Giáo trình, tài liệu | F6: Tỉnh (Thành phố)/Bộ | G6: Q1 | I6: Tỷ lệ trực tiếp | J6: 0.5
A7: Trưởng phòng | B7: 0.2 | C7: 56 | E7: Bài báo KH | F7: Quốc gia | G7: Q2/ Q3 | I7: Giảm NCKH/tháng chưa về khoa | J7: 0.1
A8: Phó Trưởng phòng | B8: 0.25 | C8: 70 | E8: Báo cáo KH | F8: Quốc tế | G8: Q4
A9: Trưởng ban trực thuộc Nhà trường | B9: 0.25 | C9: 70 | F9: ISSN
A10: Chủ nhiệm khoa | B10: 0.6 | C10: 168 | F10: HĐGSNN
A11: Chủ nhiệm khoa - BTCB | B11: 0.45 | C11: 126 | F11: WoS/Scopus
A12: Chủ nhiệm khoa - Phó BTCB | B12: 0.5 | C12: 140
A13: Phó Chủ nhiệm khoa | B13: 0.7 | C13: 196 | E13: Hướng dẫn học viên
A14: Phó Chủ nhiệm khoa - BTCB | B14: 0.55 | C14: 154 | E14: Hướng dẫn học viên thực hiện đề tài nghiên cứu khoa học | G14: Xuất sắc
A15: Phó Chủ nhiệm khoa - Phó BTCB | B15: 0.6 | C15: 168 | E15: Hướng dẫn học viên tham gia hội thi toàn quân, toàn quốc | G15: Đạt
A16: Trưởng Bộ môn | B16: 0.8 | C16: 224 | G16: Giải Nhất
A17: Trưởng Bộ môn - BTCB | B17: 0.65 | C17: 182 | G17: Giải Nhì
A18: Trưởng Bộ môn - Phó BTCB | B18: 0.7 | C18: 196 | G18: Giải Ba
A19: Giảng viên | B19: 1 | C19: 280
A20: Giảng viên kiêm Trợ lý huấn luyện | B20: 0.9 | C20: 252 | E20: Khoa
A21: Giảng viên kiêm Trợ lý kỹ thuật | B21: 0.9 | C21: 252 | E21: Khoa Khoa học xã hội & Nhân văn
A22: Giảng viên kiêm Trợ lý Huấn luyện & Kỹ thuật | B22: 0.8 | C22: 224 | E22: Khoa Quân sự
A23: CBQL/QNCN được giao giảng viên kiêm nhiệm | B23: 0.3 | C23: 84 | E23: Khoa Khoa học cơ bản
A24: Giảng viên quản lý 1 phòng/xưởng | B24: 0.95 | C24: 266 | E24: Khoa Kỹ thuật cơ sở
A25: Giảng viên quản lý nhiều phòng/xưởng | B25: 0.9 | C25: 252 | E25: Khoa Tăng thiết giáp
E26: Khoa Vũ khí
E27: Khoa Ô tô
E28: Khoa Đạn
E29: Khoa Công nghệ thông tin
E30: Khoa Tiêu chuẩn đo lường chất lượng
E31: Khoa Chỉ huy tham mưu kỹ thuật
E32: Khoa Thực hành
E33: Tiểu đoàn 1
E34: Tiểu đoàn 2
E35: Tiểu đoàn 3
E36: Tiểu đoàn 4
E37: Tiểu đoàn 5
... E44: Ban Khảo thí & ĐBCLGD-ĐT
